Workbook

Sheet DATA SISWA
A2: SEKOLAH: | B2: SD AL QUR'AN LANTABUR
A3: KELAS: | B3: 2 AL MULK
A4: TAHUN PELAJARAN: | B4: 2025/2026
A5: SEMESTER: | B5: GANJIL
A7: No | B7: Nama Siswa | C7: NIS | D7: NISN | E7: TTL | F7: LK/PR | G7: AGAMA | H7: ANAK KE | I7: JUMLAH SAUDARA KANDUNG | J7: STATUS DALAM KELUARGA | K7: ALAMAT SISWA | L7: SEKOLAH ASAL | M7: NAMA AYAH | N7: NAMA IBU | O7: PEKERJAAN AYAH | P7: PEKERJAAN IBU | Q7: NO KONTAK
A8: 1 | B8: 2 | C8: 3 | D8: 4 | E8: 5 | F8: 6 | G8: 7 | H8: 8 | I8: 9 | J8: 10 | K8: 11 | L8: 12 | M8: 13 | N8: 14 | O8: 15 | P8: 16 | Q8: 17
A9: 1 | B9: ALIFAH HANANIYYA | E9: PEKANBARU, 16 SEPTEMBER 2017 | F9: PR | G9: ISLAM | H9: 3 | I9: 3 | J9: ANAK KANDUNG | K9: JL. HANGTUAH UJUNG PERUMAHAN BMP 3 BLOK D 43, RT 03/RW 18 | L9: - | M9: KHAIRUL ASHARI | N9: MAR'ATUN SYAKIROH | O9: GURU | P9: MENGURUS RT
A10: 2 | B10: IZQIAN ARSALAN KUSUMA | E10: SIAK, 28 APRIL 2018 | F10: LK | G10: ISLAM | H10: 1 | I10: 2 | J10: ANAK KANDUNG | K10: JLN. KELILING | L10: TK AS TSAQIF KIDS | M10: EFRI DIAN KUSUMA | N10: FITRI HASTUTI | O10: WIRASWASTA
A11: 3 | B11: MUHAMAD RISQI | E11: PEKANBARU, 6 JULI 2018 | F11: LK | G11: ISLAM | H11: 1 | I11: 1 | J11: ANAK KANDUNG | K11: JL. MANGGA BESAR, RT 03/RW 08 | L11: - | M11: ADI YULIANTO | N11: ERAWATI | O11: BURUH HARIAN LEPAS | P11: MENGURUS RT
A12: 4 | B12: MUHAMMAD IBRAHIM ABDULLAH | E12: PEKANBARU, 30 MEI 2017 | F12: LK | G12: ISLAM | H12: 2 | I12: 1 | J12: ANAK KANDUNG | K12: JL. RAWA BALURAN, GG. RAWA TIRTA RT03/RW 08, TANGKERANG LABUAI | L12: TK ISLAM AL-ARSYI PEKANBARU | M12: FIRDAUS | N12: YELMI DEWISTA | O12: WIRASWASTA | P12: MENGURUS RT
A13: 5 | B13: MUHAMMAD UWAIS AL QORNI ANDIEGA | E13: PEKANBARU, 06 JULI 2016 | F13: LK | G13: ISLAM | H13: 5 | I13: 4 | J13: ANAK KANDUNG | K13: JL.MANGGA BESAR, TANGKERANG TIMUR, TENAYAN RAYA | L13: SD NEGERI 90 | M13: ANDI SAPUTRA | N13: MEGA WATI | O13: WIRASWASTA | P13: MENGURUS RT | Q13: 085265307592
A14: 6 | B14: MUSTOFA ABDUL KARIM BENZEMA | E14: PEKANBARU, 4 JUNI 2017 | F14: LK | G14: ISLAM | H14: 4 | I14: 3 | J14: ANAK KANDUNG | K14: JL. KAPAU SARI IX, GG. KAPAU SARI IX/5, RT 03/RW07 | L14: TK TAHFIDZ F3 PEKANBARU | M14: MUTHOLIB | N14: ARIFIA FUSILA | O14: WIRAUSAHA | P14: MENGURUS RT
A15: 7 | B15: RAZAN MUMTAZAH ZUBAIR | E15: POLEWALI MANDAR, 5 JUNI 2018 | F15: PR | G15: ISLAM | H15: 4 | I15: 3 | J15: ANAK KANDUNG | K15: JL. HANGTUAH UJUNG 311, RT 2/RW 9 | L15: TK IT ALJARIYAH POLMAN | M15: DESRENI | N15: SUBAER LOPA | O15: - | P15: MENGURUS RT
A16: 8 | B16: SHOFIYYAH MIZYANAH | E16: PEKANBARU, 22 FEBRUARI 2017 | F16: PR | G16: ISLAM | H16: 2 | I16: 2 | J16: ANAK KANDUNG | K16: JL. INDRAPURI UJUNG KOMPLEKPESANTREN HIDAYATULLAH, RT 03/RW 05 | L16: TK TAHFIDZ YAA BUNAYYA | M16: MUHAMMAD JA'FAR SHIDIQ | N16: NAWIRTHA | O16: WIRASWASTA | P16: WIRASWASTA

Sheet PAI
AJ2: PERSENTASE NILAI
AJ3: 0.9 | AK3: 0.1
A4: NO | B4: NAMA SISWA | C4: FORMATIF 1 | M4: RERATA 1 | N4: FORMATIF 2 | X4: RERATA 2 | Y4: FORMATIF 3 | AI4: RERATA 3 | AJ4: RERATA FORMATIF | AK4: NILAI SUMATIF | AL4: NILAI RAPOR | AM4: PEMBULATAN NILAI RAPOR
C5: 1 | D5: 2 | E5: 3 | F5: 4 | G5: 5 | H5: 6 | I5: 7 | J5: 8 | K5: 9 | L5: 10 | N5: 1 | O5: 2 | P5: 3 | Q5: 4 | R5: 5 | S5: 6 | T5: 7 | U5: 8 | V5: 9 | W5: 10 | Y5: 1 | Z5: 2 | AA5: 3 | AB5: 4 | AC5: 5 | AD5: 6 | AE5: 7 | AF5: 8 | AG5: 9 | AH5: 10
A6: 1 | B6: ALIFAH HANANIYYA | M6: =AVERAGE(C6:L6) -> #DIV/0! | X6: =AVERAGE(N6:W6) -> #DIV/0! | Y6: 100 | Z6: 100 | AA6: 40 | AB6: 100 | AI6: =AVERAGE(Y6:AH6) -> 85 | AJ6: =AVERAGE(X6,AI6) -> #DIV/0! | AK6: 96 | AL6: =SUMPRODUCT($AJ$3:$AK$3,AJ6:AK6) -> #DIV/0! | AM6: =ROUND(AL6,0) -> #DIV/0!
A7: 2 | B7: IZQIAN ARSALAN KUSUMA | M7: =AVERAGE(C7:L7) -> #DIV/0! | X7: =AVERAGE(N7:W7) -> #DIV/0! | Z7: 60 | AB7: 100 | AI7: =AVERAGE(Y7:AH7) -> 80 | AJ7: =AVERAGE(X7,AI7) -> #DIV/0! | AK7: 90 | AL7: =SUMPRODUCT($AJ$3:$AK$3,AJ7:AK7) -> #DIV/0! | AM7: =ROUND(AL7,0) -> #DIV/0!
A8: 3 | B8: MUHAMAD RISQI | M8: =AVERAGE(C8:L8) -> #DIV/0! | X8: =AVERAGE(N8:W8) -> #DIV/0! | Y8: 80 | AB8: 100 | AI8: =AVERAGE(Y8:AH8) -> 90 | AJ8: =AVERAGE(X8,AI8) -> #DIV/0! | AL8: =SUMPRODUCT($AJ$3:$AK$3,AJ8:AK8) -> #DIV/0! | AM8: =ROUND(AL8,0) -> #DIV/0!
A9: 4 | B9: MUHAMMAD IBRAHIM ABDULLAH | M9: =AVERAGE(C9:L9) -> #DIV/0! | X9: =AVERAGE(N9:W9) -> #DIV/0! | Y9: 80 | AA9: 20 | AB9: 60 | AI9: =AVERAGE(Y9:AH9) -> 53.333333 | AJ9: =AVERAGE(X9,AI9) -> #DIV/0! | AK9: 60 | AL9: =SUMPRODUCT($AJ$3:$AK$3,AJ9:AK9) -> #DIV/0! | AM9: =ROUND(AL9,0) -> #DIV/0!
A10: 5 | B10: MUHAMMAD UWAIS AL QORNI ANDIEGA | M10: =AVERAGE(C10:L10) -> #DIV/0! | X10: =AVERAGE(N10:W10) -> #DIV/0! | Y10: 80 | AB10: 100 | AI10: =AVERAGE(Y10:AH10) -> 90 | AJ10: =AVERAGE(X10,AI10) -> #DIV/0! | AK10: 73 | AL10: =SUMPRODUCT($AJ$3:$AK$3,AJ10:AK10) -> #DIV/0! | AM10: =ROUND(AL10,0) -> #DIV/0!
A11: 6 | B11: MUSTOFA ABDUL KARIM BENZEMA | M11: =AVERAGE(C11:L11) -> #DIV/0! | X11: =AVERAGE(N11:W11) -> #DIV/0! | Y11: 80 | AB11: 100 | AI11: =AVERAGE(Y11:AH11) -> 90 | AJ11: =AVERAGE(X11,AI11) -> #DIV/0! | AK11: 100 | AL11: =SUMPRODUCT($AJ$3:$AK$3,AJ11:AK11) -> #DIV/0! | AM11: =ROUND(AL11,0) -> #DIV/0!
A12: 7 | B12: RAZAN MUMTAZAH ZUBAIR | M12: =AVERAGE(C12:L12) -> #DIV/0! | X12: =AVERAGE(N12:W12) -> #DIV/0! | Y12: 80 | AA12: 40 | AB12: 100 | AI12: =AVERAGE(Y12:AH12) -> 73.333333 | AJ12: =AVERAGE(X12,AI12) -> #DIV/0! | AK12: 91 | AL12: =SUMPRODUCT($AJ$3:$AK$3,AJ12:AK12) -> #DIV/0! | AM12: =ROUND(AL12,0) -> #DIV/0!
A13: 8 | B13: SHOFIYYAH MIZYANAH | M13: =AVERAGE(C13:L13) -> #DIV/0! | X13: =AVERAGE(N13:W13) -> #DIV/0! | Y13: 100 | Z13: 100 | AB13: 100 | AI13: =AVERAGE(Y13:AH13) -> 100 | AJ13: =AVERAGE(X13,AI13) -> #DIV/0! | AK13: 100 | AL13: =SUMPRODUCT($AJ$3:$AK$3,AJ13:AK13) -> #DIV/0! | AM13: =ROUND(AL13,0) -> #DIV/0!

Sheet LITERASI
AF2: PERSENTASE NILAI
AF3: 0.9 | AG3: 0.1
A4: NO | B4: NAMA SISWA | C4: FORMATIF 1 | M4: RERATA 1 | N4: FORMATIF 3 | V4: RERATA 2 | W4: FORMATIF 4 | AE4: RERATA 3 | AF4: RERATA FORMATIF | AG4: NILAI SUMATIF | AH4: NILAI RAPOR | AI4: PEMBULATAN NILAI RAPOR
C5: 1 | D5: 2 | E5: 3 | F5: 4 | G5: 5 | H5: 6 | I5: 7 | J5: 8 | K5: 9 | L5: 10 | N5: 1 | O5: 2 | P5: 3 | Q5: 4 | R5: 5 | S5: 6 | T5: 7 | U5: 8 | W5: 1 | X5: 2 | Y5: 3 | Z5: 4 | AA5: 5 | AB5: 6 | AC5: 7 | AD5: 8
A6: 1 | B6: ALIFAH HANANIYYA | M6: =AVERAGE(C6:L6) -> #DIV/0! | O6: 100 | P6: 100 | Q6: 100 | R6: 100 | S6: 90 | T6: 100 | V6: =AVERAGE(N6:U6) -> 98.333333 | AE6: =AVERAGE(W6:AD6) -> #DIV/0! | AF6: =AVERAGE(V6,AE6) -> #DIV/0! | AG6: 72 | AH6: =SUMPRODUCT($AF$3:$AG$3,AF6:AG6) -> #DIV/0! | AI6: =ROUND(AH6,0) -> #DIV/0!
A7: 2 | B7: IZQIAN ARSALAN KUSUMA | M7: =AVERAGE(C7:L7) -> #DIV/0! | N7: 100 | O7: 100 | P7: 100 | R7: 95 | S7: 100 | T7: 100 | V7: =AVERAGE(N7:U7) -> 99.166667 | AE7: =AVERAGE(W7:AD7) -> #DIV/0! | AF7: =AVERAGE(V7,AE7) -> #DIV/0! | AG7: 79 | AH7: =SUMPRODUCT($AF$3:$AG$3,AF7:AG7) -> #DIV/0! | AI7: =ROUND(AH7,0) -> #DIV/0!
A8: 3 | B8: MUHAMAD RISQI | M8: =AVERAGE(C8:L8) -> #DIV/0! | O8: 100 | P8: 100 | V8: =AVERAGE(N8:U8) -> 100 | AE8: =AVERAGE(W8:AD8) -> #DIV/0! | AF8: =AVERAGE(V8,AE8) -> #DIV/0! | AH8: =SUMPRODUCT($AF$3:$AG$3,AF8:AG8) -> #DIV/0! | AI8: =ROUND(AH8,0) -> #DIV/0!
A9: 4 | B9: MUHAMMAD IBRAHIM ABDULLAH | M9: =AVERAGE(C9:L9) -> #DIV/0! | N9: 50 | O9: 100 | P9: 100 | R9: 100 | S9: 100 | T9: 40 | V9: =AVERAGE(N9:U9) -> 81.666667 | AE9: =AVERAGE(W9:AD9) -> #DIV/0! | AF9: =AVERAGE(V9,AE9) -> #DIV/0! | AG9: 41 | AH9: =SUMPRODUCT($AF$3:$AG$3,AF9:AG9) -> #DIV/0! | AI9: =ROUND(AH9,0) -> #DIV/0!
A10: 5 | B10: MUHAMMAD UWAIS AL QORNI ANDIEGA | M10: =AVERAGE(C10:L10) -> #DIV/0! | N10: 90 | O10: 100 | P10: 100 | Q10: 100 | R10: 60 | S10: 85 | T10: 100 | V10: =AVERAGE(N10:U10) -> 90.714286 | AE10: =AVERAGE(W10:AD10) -> #DIV/0! | AF10: =AVERAGE(V10,AE10) -> #DIV/0! | AG10: 75 | AH10: =SUMPRODUCT($AF$3:$AG$3,AF10:AG10) -> #DIV/0! | AI10: =ROUND(AH10,0) -> #DIV/0!
A11: 6 | B11: MUSTOFA ABDUL KARIM BENZEMA | M11: =AVERAGE(C11:L11) -> #DIV/0! | N11: 100 | O11: 100 | P11: 100 | Q11: 100 | R11: 100 | S11: 85 | T11: 100 | V11: =AVERAGE(N11:U11) -> 97.857143 | AE11: =AVERAGE(W11:AD11) -> #DIV/0! | AF11: =AVERAGE(V11,AE11) -> #DIV/0! | AG11: 91 | AH11: =SUMPRODUCT($AF$3:$AG$3,AF11:AG11) -> #DIV/0! | AI11: =ROUND(AH11,0) -> #DIV/0!
A12: 7 | B12: RAZAN MUMTAZAH ZUBAIR | M12: =AVERAGE(C12:L12) -> #DIV/0! | N12: 90 | O12: 100 | P12: 100 | R12: 95 | S12: 80 | T12: 100 | V12: =AVERAGE(N12:U12) -> 94.166667 | AE12: =AVERAGE(W12:AD12) -> #DIV/0! | AF12: =AVERAGE(V12,AE12) -> #DIV/0! | AG12: 95 | AH12: =SUMPRODUCT($AF$3:$AG$3,AF12:AG12) -> #DIV/0! | AI12: =ROUND(AH12,0) -> #DIV/0!
A13: 8 | B13: SHOFIYYAH MIZYANAH | M13: =AVERAGE(C13:L13) -> #DIV/0! | N13: 100 | O13: 100 | P13: 100 | V13: =AVERAGE(N13:U13) -> 100 | AE13: =AVERAGE(W13:AD13) -> #DIV/0! | AF13: =AVERAGE(V13,AE13) -> #DIV/0! | AG13: 94 | AH13: =SUMPRODUCT($AF$3:$AG$3,AF13:AG13) -> #DIV/0! | AI13: =ROUND(AH13,0) -> #DIV/0!

Sheet SAINS (MATH)
AG2: PERSENTASE NILAI
AG3: 0.9 | AH3: 0.1
A4: NO | B4: NAMA SISWA | C4: FORMATIF 2 | M4: RERATA 2 | N4: FORMATIF 3 | W4: RERATA 3 | X4: FORMATIF 4 | AF4: RERATA 4 | AG4: RERATA FORMATIF | AH4: NILAI SUMATIF | AI4: NILAI RAPOR | AJ4: PEMBULATAN NILAI RAPOR
C5: 1 | D5: 2 | E5: 3 | F5: 4 | G5: 5 | H5: 6 | I5: 7 | J5: 8 | K5: 9 | L5: 10 | N5: 1 | O5: 2 | P5: 3 | Q5: 4 | R5: 5 | S5: 6 | T5: 7 | U5: 8 | V5: 9 | X5: 1 | Y5: 2 | Z5: 3 | AA5: 4 | AB5: 5 | AC5: 6 | AD5: 7 | AE5: 8
A6: 1 | B6: ALIFAH HANANIYYA | M6: =AVERAGE(C6:L6) -> #DIV/0! | N6: 100 | O6: 98 | P6: 80 | Q6: 95 | R6: 100 | S6: 100 | W6: =AVERAGE(O6:V6) -> 94.6 | X6: 90 | Y6: 100 | Z6: 100 | AF6: =AVERAGE(X6:AE6) -> 96.666667 | AG6: =AVERAGE(W6,AF6) -> 95.633333 | AH6: 92 | AI6: =SUMPRODUCT($AG$3:$AH$3,AG6:AH6) -> 95.27 | AJ6: =ROUND(AI6,0) -> 95
A7: 2 | B7: IZQIAN ARSALAN KUSUMA | M7: =AVERAGE(C7:L7) -> #DIV/0! | N7: 100 | O7: 100 | P7: 100 | Q7: 100 | R7: 100 | S7: 100 | W7: =AVERAGE(N7:V7) -> 100 | X7: 85 | Y7: 100 | Z7: 90 | AF7: =AVERAGE(X7:AE7) -> 91.666667 | AG7: =AVERAGE(W7,AF7) -> 95.833333 | AH7: 93 | AI7: =SUMPRODUCT($AG$3:$AH$3,AG7:AH7) -> 95.55 | AJ7: =ROUND(AI7,0) -> 96
A8: 3 | B8: MUHAMAD RISQI | M8: =AVERAGE(C8:L8) -> #DIV/0! | N8: 0 | O8: 54 | P8: 80 | Q8: 50 | R8: 50 | S8: 50 | W8: =AVERAGE(N8:V8) -> 47.333333 | X8: 0 | Y8: 50 | Z8: 0 | AF8: =AVERAGE(X8:AE8) -> 16.666667 | AG8: =AVERAGE(W8,AF8) -> 32 | AI8: =SUMPRODUCT($AG$3:$AH$3,AG8:AH8) -> 28.8 | AJ8: =ROUND(AI8,0) -> 29
A9: 4 | B9: MUHAMMAD IBRAHIM ABDULLAH | M9: =AVERAGE(C9:L9) -> #DIV/0! | N9: 100 | O9: 100 | P9: 95 | Q9: 100 | R9: 100 | S9: 95 | W9: =AVERAGE(N9:V9) -> 98.333333 | X9: 100 | Y9: 75 | Z9: 90 | AF9: =AVERAGE(X9:AE9) -> 88.333333 | AG9: =AVERAGE(W9,AF9) -> 93.333333 | AH9: 75 | AI9: =SUMPRODUCT($AG$3:$AH$3,AG9:AH9) -> 91.5 | AJ9: =ROUND(AI9,0) -> 92
A10: 5 | B10: MUHAMMAD UWAIS AL QORNI ANDIEGA | M10: =AVERAGE(C10:L10) -> #DIV/0! | N10: 100 | O10: 94 | P10: 100 | Q10: 100 | W10: =AVERAGE(N10:V10) -> 98.5 | X10: 50 | Y10: 90 | AF10: =AVERAGE(X10:AE10) -> 70 | AG10: =AVERAGE(W10,AF10) -> 84.25 | AH10: 92 | AI10: =SUMPRODUCT($AG$3:$AH$3,AG10:AH10) -> 85.025 | AJ10: =ROUND(AI10,0) -> 85
A11: 6 | B11: MUSTOFA ABDUL KARIM BENZEMA | M11: =AVERAGE(C11:L11) -> #DIV/0! | N11: 90 | O11: 100 | P11: 100 | Q11: 100 | R11: 100 | S11: 99 | W11: =AVERAGE(N11:V11) -> 98.166667 | X11: 80 | Y11: 100 | Z11: 85 | AF11: =AVERAGE(X11:AE11) -> 88.333333 | AG11: =AVERAGE(W11,AF11) -> 93.25 | AH11: 87 | AI11: =SUMPRODUCT($AG$3:$AH$3,AG11:AH11) -> 92.625 | AJ11: =ROUND(AI11,0) -> 93
A12: 7 | B12: RAZAN MUMTAZAH ZUBAIR | M12: =AVERAGE(C12:L12) -> #DIV/0! | N12: 80 | O12: 75 | P12: 100 | Q12: 95 | R12: 100 | S12: 94 | W12: =AVERAGE(N12:V12) -> 90.666667 | X12: 60 | Y12: 90 | Z12: 100 | AF12: =AVERAGE(X12:AE12) -> 83.333333 | AG12: =AVERAGE(W12,AF12) -> 87 | AH12: 95 | AI12: =SUMPRODUCT($AG$3:$AH$3,AG12:AH12) -> 87.8 | AJ12: =ROUND(AI12,0) -> 88
A13: 8 | B13: SHOFIYYAH MIZYANAH | M13: =AVERAGE(C13:L13) -> #DIV/0! | N13: 100 | O13: 100 | P13: 100 | Q13: 100 | R13: 100 | S13: 100 | W13: =AVERAGE(N13:V13) -> 100 | X13: 100 | Y13: 100 | Z13: 80 | AF13: =AVERAGE(X13:AE13) -> 93.333333 | AG13: =AVERAGE(W13,AF13) -> 96.666667 | AH13: 96 | AI13: =SUMPRODUCT($AG$3:$AH$3,AG13:AH13) -> 96.6 | AJ13: =ROUND(AI13,0) -> 97

Sheet ADAB
AJ2: PERSENTASE NILAI
AJ3: 0.9 | AK3: 0.1
A4: NO | B4: NAMA SISWA | C4: FORMATIF 1 | M4: RERATA 1 | N4: FORMATIF 2 | X4: RERATA 2 | Y4: FORMATIF 3 | AI4: RERATA 3 | AJ4: RERATA FORMATIF | AK4: NILAI SUMATIF | AL4: NILAI RAPOR | AM4: PEMBULATAN NILAI RAPOR
C5: 1 | D5: 2 | E5: 3 | F5: 4 | G5: 5 | H5: 6 | I5: 7 | J5: 8 | K5: 9 | L5: 10 | N5: 1 | O5: 2 | P5: 3 | Q5: 4 | R5: 5 | S5: 6 | T5: 7 | U5: 8 | V5: 9 | W5: 10 | Y5: 1 | Z5: 2 | AA5: 3 | AB5: 4 | AC5: 5 | AD5: 6 | AE5: 7 | AF5: 8 | AG5: 9 | AH5: 10
A6: 1 | B6: ALIFAH HANANIYYA | M6: =AVERAGE(C6:L6) -> #DIV/0! | X6: =AVERAGE(N6:W6) -> #DIV/0! | Z6: 100 | AA6: 100 | AB6: 100 | AI6: =AVERAGE(Y6:AH6) -> 100 | AJ6: =AVERAGE(M6,X6,AI6) -> #DIV/0! | AK6: 96 | AL6: =SUMPRODUCT($AJ$3:$AK$3,AJ6:AK6) -> #DIV/0! | AM6: =ROUND(AL6,0) -> #DIV/0!
A7: 2 | B7: IZQIAN ARSALAN KUSUMA | M7: =AVERAGE(C7:L7) -> #DIV/0! | X7: =AVERAGE(N7:W7) -> #DIV/0! | Y7: 80 | AA7: 100 | AB7: 100 | AI7: =AVERAGE(Y7:AH7) -> 93.333333 | AJ7: =AVERAGE(M7,X7,AI7) -> #DIV/0! | AK7: 96 | AL7: =SUMPRODUCT($AJ$3:$AK$3,AJ7:AK7) -> #DIV/0! | AM7: =ROUND(AL7,0) -> #DIV/0!
A8: 3 | B8: MUHAMAD RISQI | M8: =AVERAGE(C8:L8) -> #DIV/0! | X8: =AVERAGE(N8:W8) -> #DIV/0! | Y8: 60 | Z8: 100 | AB8: 100 | AI8: =AVERAGE(Y8:AH8) -> 86.666667 | AJ8: =AVERAGE(M8,X8,AI8) -> #DIV/0! | AK8: 80 | AL8: =SUMPRODUCT($AJ$3:$AK$3,AJ8:AK8) -> #DIV/0! | AM8: =ROUND(AL8,0) -> #DIV/0!
A9: 4 | B9: MUHAMMAD IBRAHIM ABDULLAH | M9: =AVERAGE(C9:L9) -> #DIV/0! | X9: =AVERAGE(N9:W9) -> #DIV/0! | Y9: 40 | AA9: 100 | AB9: 100 | AI9: =AVERAGE(Y9:AH9) -> 80 | AJ9: =AVERAGE(M9,X9,AI9) -> #DIV/0! | AK9: 68 | AL9: =SUMPRODUCT($AJ$3:$AK$3,AJ9:AK9) -> #DIV/0! | AM9: =ROUND(AL9,0) -> #DIV/0!
A10: 5 | B10: MUHAMMAD UWAIS AL QORNI ANDIEGA | M10: =AVERAGE(C10:L10) -> #DIV/0! | X10: =AVERAGE(N10:W10) -> #DIV/0! | Y10: 100 | Z10: 100 | AA10: 100 | AB10: 100 | AI10: =AVERAGE(Y10:AH10) -> 100 | AJ10: =AVERAGE(M10,X10,AI10) -> #DIV/0! | AK10: 84 | AL10: =SUMPRODUCT($AJ$3:$AK$3,AJ10:AK10) -> #DIV/0! | AM10: =ROUND(AL10,0) -> #DIV/0!
A11: 6 | B11: MUSTOFA ABDUL KARIM BENZEMA | M11: =AVERAGE(C11:L11) -> #DIV/0! | X11: =AVERAGE(N11:W11) -> #DIV/0! | Y11: 100 | Z11: 100 | AA11: 100 | AB11: 100 | AI11: =AVERAGE(Y11:AH11) -> 100 | AJ11: =AVERAGE(M11,X11,AI11) -> #DIV/0! | AK11: 98 | AL11: =SUMPRODUCT($AJ$3:$AK$3,AJ11:AK11) -> #DIV/0! | AM11: =ROUND(AL11,0) -> #DIV/0!
A12: 7 | B12: RAZAN MUMTAZAH ZUBAIR | M12: =AVERAGE(C12:L12) -> #DIV/0! | X12: =AVERAGE(N12:W12) -> #DIV/0! | Y12: 100 | AA12: 100 | AB12: 100 | AI12: =AVERAGE(Y12:AH12) -> 100 | AJ12: =AVERAGE(M12,X12,AI12) -> #DIV/0! | AK12: 100 | AL12: =SUMPRODUCT($AJ$3:$AK$3,AJ12:AK12) -> #DIV/0! | AM12: =ROUND(AL12,0) -> #DIV/0!
A13: 8 | B13: SHOFIYYAH MIZYANAH | M13: =AVERAGE(C13:L13) -> #DIV/0! | X13: =AVERAGE(N13:W13) -> #DIV/0! | Y13: 100 | Z13: 100 | AA13: 100 | AB13: 100 | AI13: =AVERAGE(Y13:AH13) -> 100 | AJ13: =AVERAGE(M13,X13,AI13) -> #DIV/0! | AK13: 98 | AL13: =SUMPRODUCT($AJ$3:$AK$3,AJ13:AK13) -> #DIV/0! | AM13: =ROUND(AL13,0) -> #DIV/0!

Sheet REKAP
A3: NO | B3: NAMA SISWA | C3: NILAI RAPOR | G3: PRAKTIK | N3: JUMLAH | O3: RATA-RATA | P3: RANGKING | Q3: KEHADIRAN
C4: PAI | D4: LITERASI | E4: SAINS(MATH) | F4: ADAB | G4: PAI | J4: ADAB | Q4: S | R4: I | S4: A
A5: 1 | B5: 2 | C5: 3 | D5: 4 | E5: 5 | F5: 6 | G5: 7 | H5: 8 | I5: 9 | J5: 10 | K5: 11 | L5: 12 | M5: 13 | N5: 14 | O5: 15 | P5: 16 | Q5: 17 | R5: 18 | S5: 19
A6: 1 | B6: ALIFAH HANANIYYA | C6: =PAI!AM6 -> #DIV/0! | D6: =LITERASI!AI6 -> #DIV/0! | E6: ='SAINS (MATH)'!AJ6 -> 95 | F6: =ADAB!AM6 -> #DIV/0! | G6: 90 | H6: 100 | I6: 97 | N6: =SUM(C6:M6) -> #DIV/0! | O6: =AVERAGE(C6:M6) -> #DIV/0! | P6: =RANK(N6,$N$6:$N$13,0) -> #DIV/0! | Q6: 4 | R6: 0 | S6: 6
A7: 2 | B7: IZQIAN ARSALAN KUSUMA | C7: =PAI!AM7 -> #DIV/0! | D7: =LITERASI!AI7 -> #DIV/0! | E7: ='SAINS (MATH)'!AJ7 -> 96 | F7: =ADAB!AM7 -> #DIV/0! | G7: 90 | H7: 100 | I7: 95 | N7: =SUM(C7:M7) -> #DIV/0! | O7: =AVERAGE(C7:M7) -> #DIV/0! | P7: =RANK(N7,$N$6:$N$13,0) -> #DIV/0! | Q7: 12 | R7: 2 | S7: 0
A8: 3 | B8: MUHAMAD RISQI | C8: =PAI!AM8 -> #DIV/0! | D8: =LITERASI!AI8 -> #DIV/0! | E8: ='SAINS (MATH)'!AJ8 -> 29 | F8: =ADAB!AM8 -> #DIV/0! | G8: 100 | H8: 100 | I8: 73 | N8: =SUM(C8:M8) -> #DIV/0! | O8: =AVERAGE(C8:M8) -> #DIV/0! | P8: =RANK(N8,$N$6:$N$13,0) -> #DIV/0! | Q8: 8 | R8: 1 | S8: 4
A9: 4 | B9: MUHAMMAD IBRAHIM ABDULLAH | C9: =PAI!AM9 -> #DIV/0! | D9: =LITERASI!AI9 -> #DIV/0! | E9: ='SAINS (MATH)'!AJ9 -> 92 | F9: =ADAB!AM9 -> #DIV/0! | G9: 100 | H9: 100 | I9: 92 | N9: =SUM(C9:M9) -> #DIV/0! | O9: =AVERAGE(C9:M9) -> #DIV/0! | P9: =RANK(N9,$N$6:$N$13,0) -> #DIV/0! | Q9: 9 | R9: 1 | S9: 1
A10: 5 | B10: MUHAMMAD UWAIS AL QORNI ANDIEGA | C10: =PAI!AM10 -> #DIV/0! | D10: =LITERASI!AI10 -> #DIV/0! | E10: ='SAINS (MATH)'!AJ10 -> 85 | F10: =ADAB!AM10 -> #DIV/0! | G10: 85 | H10: 100 | I10: 95 | N10: =SUM(C10:M10) -> #DIV/0! | O10: =AVERAGE(C10:M10) -> #DIV/0! | P10: =RANK(N10,$N$6:$N$13,0) -> #DIV/0! | Q10: 8 | R10: 3 | S10: 7
A11: 6 | B11: MUSTOFA ABDUL KARIM BENZEMA | C11: =PAI!AM11 -> #DIV/0! | D11: =LITERASI!AI11 -> #DIV/0! | E11: ='SAINS (MATH)'!AJ11 -> 93 | F11: =ADAB!AM11 -> #DIV/0! | G11: 85 | H11: 100 | I11: 95 | N11: =SUM(C11:M11) -> #DIV/0! | O11: =AVERAGE(C11:M11) -> #DIV/0! | P11: =RANK(N11,$N$6:$N$13,0) -> #DIV/0! | Q11: 10 | R11: 2 | S11: 2
A12: 7 | B12: RAZAN MUMTAZAH ZUBAIR | C12: =PAI!AM12 -> #DIV/0! | D12: =LITERASI!AI12 -> #DIV/0! | E12: ='SAINS (MATH)'!AJ12 -> 88 | F12: =ADAB!AM12 -> #DIV/0! | G12: 90 | H12: 90 | I12: 97 | N12: =SUM(C12:M12) -> #DIV/0! | O12: =AVERAGE(C12:M12) -> #DIV/0! | P12: =RANK(N12,$N$6:$N$13,0) -> #DIV/0! | Q12: 8 | R12: 4 | S12: 0
A13: 8 | B13: SHOFIYYAH MIZYANAH | C13: =PAI!AM13 -> #DIV/0! | D13: =LITERASI!AI13 -> #DIV/0! | E13: ='SAINS (MATH)'!AJ13 -> 97 | F13: =ADAB!AM13 -> #DIV/0! | G13: 90 | H13: 85 | I13: 97 | N13: =SUM(C13:M13) -> #DIV/0! | O13: =AVERAGE(C13:M13) -> #DIV/0! | P13: =RANK(N13,$N$6:$N$13,0) -> #DIV/0! | Q13: 5 | R13: 0 | S13: 10

Sheet RAPOR
C3: LAPORAN PENCAPAIAN KOMPETENSI PESERTA DIDIK SEKOLAH DASAR AL QUR'AN LANTABUR PEKANBARU
A8: NAMA PESERTA DIDIK | E8: : | F8: =VLOOKUP(P15,'DATA SISWA'!A9:Q19,2,0) -> MUHAMMAD IBRAHIM ABDULLAH
A9: NAMA SEKOLAH | E9: : | F9: ='[1]DATA SISWA'!C3 -> SD AL QUR'AN LANTABUR
A10: KELAS | E10: : | F10: 2 AL MULK
A11: SEMESTER | E11: : | F11: GANJIL
A13: NO | B13: NAMA PELAJARAN | C13: KKM | D13: NILAI | E13: PREDIKAT | F13: DESKRIPSI
A14: 1 | B14: PAI | C14: 75 | D14: =VLOOKUP($P$15,REKAP!A6:S15,3,0) -> #DIV/0! | E14: =VLOOKUP(D14,$P$22:$Q$24,2,1) -> #DIV/0! | F14: =VLOOKUP($P$15,DESKRIPSI!$A$6:$F$13,3,0) -> 0 | P14: NOMOR URUT
A15: 2 | B15: LITERASI | C15: 75 | D15: =VLOOKUP($P$15,REKAP!A6:S15,4,0) -> #DIV/0! | E15: =VLOOKUP(D15,$P$22:$Q$24,2,1) -> #DIV/0! | F15: =VLOOKUP($P$15,DESKRIPSI!$A$6:$F$13,4,0) -> 0 | P15: 4
A16: 3 | B16: SAINS (MATH) | C16: 75 | D16: =VLOOKUP($P$15,REKAP!A6:S15,5,0) -> 92 | E16: =VLOOKUP(D16,$P$22:$Q$24,2,1) -> A | F16: =VLOOKUP($P$15,DESKRIPSI!$A$6:$F$13,5,0) -> Ananda IBRAHIM sangat baik dalam memahami materi penjumlahan dan bangun datar. Perlu berlatih lebih sering lagi pada materi pengurangan dan posisi benda.
A17: 4 | B17: ADAB | C17: 75 | D17: =VLOOKUP($P$15,REKAP!A6:S15,6,0) -> #DIV/0! | E17: =VLOOKUP(D17,$P$22:$Q$24,2,1) -> #DIV/0! | F17: =VLOOKUP($P$15,DESKRIPSI!$A$6:$F$13,6,0) -> 0
A18: TOTAL NILAI | D18: =SUM(D14:D17) -> #DIV/0!
A19: RATA-RATA NILAI | D19: =AVERAGE(D14:D17) -> #DIV/0!
A22: KETIDAKHADIRAN | F22: NILAI | G22: PREDIKAT | H22: KETERANGAN | P22: 75 | Q22: C
A23: 1 | B23: SAKIT | C23: =VLOOKUP($P$15,REKAP!A6:S15,17,0) -> 9 | F23: 91-100 | G23: A | H23: SANGAT BAIK | P23: 83 | Q23: B
A24: 2 | B24: IZIN | C24: =VLOOKUP($P$15,REKAP!A6:S15,18,0) -> 1 | F24: 83-90 | G24: B | H24: BAIK | P24: 91 | Q24: A
A25: 3 | B25: TANPA KETERANGAN | C25: =VLOOKUP($P$15,REKAP!A6:S15,19,0) -> 1 | F25: 75-82 | G25: C | H25: CUKUP BAIK
B28: Mengetahui: | H28: Pekanbaru, 19 Desember 2025
B29: Orang Tua/Wali | H29: Wali Kelas 2 Al Mulk
B32: =VLOOKUP(RAPOR!$P$15,'DATA SISWA'!$A$9:$Q$18,13,0) -> FIRDAUS | H32: NINING WAHYUNI, S.I.Kom
E33: Kepala Sekolah | H33: NIY. 2403002
E36: KASMIDAR, S.Pd
E37: NIY. 2403001

Sheet PRAKTIK
B3: LAPORAN PENCAPAIAN KOMPETENSI PESERTA DIDIK SEKOLAH DASAR AL QUR'AN LANTABUR PEKANBARU
A8: NAMA PESERTA DIDIK | E8: : | F8: ='DATA SISWA'!B9 -> ALIFAH HANANIYYA
A9: NAMA SEKOLAH | E9: : | F9: SD AL QUR'AN LANTABUR
A10: KELAS | E10: : | F10: 2 AL MULK
A11: SEMESTER | E11: : | F11: GANJIL
A12: TAHUN PELAJARAN | E12: : | F12: 2025/2026
A14: PRAKTIK PAI
A15: KATEGORI | C15: KKM | D15: NILAI | E15: DESKRIPSI
A16: Adzan | C16: 75 | D16: 90
A17: Iqomah | C17: 75 | D17: 100
A18: Shalat Jum'at | C18: 75 | D18: 97
A20: PRAKTIK ADAB
A21: KATEGORI | C21: KKM | D21: NILAI | E21: DESKRIPSI
A22: Adab kepada Allah | C22: 75
A23: Adab kepada diri sendiri | C23: 75
A24: Adab kepada orang tua | C24: 75
A25: Adab kepada guru | C25: 75
A28: Mengetahui: | I28: Pekanbaru, 19 Desember 2025
A29: Orang Tua/Wali | I29: Wali Kelas 2 Al Mulk
A32: ='DATA SISWA'!M9 -> KHAIRUL ASHARI | I32: NINING WAHYUNI, S.I.Kom
I33: NIY. 2403002
D34: Kepala Sekolah
D37: KASMIDAR, S.Pd
D38: NIY. 2403001
B44: LAPORAN PENCAPAIAN KOMPETENSI PESERTA DIDIK SEKOLAH DASAR AL QUR'AN LANTABUR PEKANBARU
A49: NAMA PESERTA DIDIK | E49: : | F49: ='DATA SISWA'!B10 -> IZQIAN ARSALAN KUSUMA
A50: NAMA SEKOLAH | E50: : | F50: SD AL QUR'AN LANTABUR
A51: KELAS | E51: : | F51: 2 AL MULK
A52: SEMESTER | E52: : | F52: GANJIL
A53: TAHUN PELAJARAN | E53: : | F53: 2025/2026
A55: PRAKTIK PAI
A56: KATEGORI | C56: KKM | D56: NILAI | E56: DESKRIPSI
A57: Adzan | C57: 75 | D57: 90
A58: Iqomah | C58: 75 | D58: 100
A59: Shalat Jum'at | C59: 75 | D59: 95
A61: PRAKTIK ADAB
A62: KATEGORI | C62: KKM | D62: NILAI | E62: DESKRIPSI
A63: Adab kepada Allah | C63: 75
A64: Adab kepada diri sendiri | C64: 75
A65: Adab kepada orang tua | C65: 75
...

Sheet DESKRIPSI
A3: NO | B3: NAMA | C3: DESKRIPSI
C4: PAI | D4: LITERASI | E4: SAINS (MATH) | F4: ADAB
A5: 1 | B5: 2 | C5: 3 | D5: 4 | E5: 5 | F5: 6
A6: 1 | B6: ALIFAH HANANIYYA | C6: fghhh | E6: Ananda ALIFAH sangat baik dalam memahami materi operasi hitung, bangun datar, dan posisi benda.
A7: 2 | B7: IZQIAN ARSALAN KUSUMA | E7: Ananda ARSALAN sangat baik dalam memahami materi operasi hitung, bangun datar, dan posisi benda.
A8: 3 | B8: MUHAMAD RISQI | E8: Ananda RISQI perlu belajar lebih giat dan serius lagi dalam memahami materi operasi hitung, bangun datar, dan posisi benda. Mohon bimbingan dan kerjasama orang tua di rumah.
A9: 4 | B9: MUHAMMAD IBRAHIM ABDULLAH | E9: Ananda IBRAHIM sangat baik dalam memahami materi penjumlahan dan bangun datar. Perlu berlatih lebih sering lagi pada materi pengurangan dan posisi benda.
A10: 5 | B10: MUHAMMAD UWAIS AL QORNI ANDIEGA | E10: Ananda UWAIS baik dalam memahami materi operasi hitung, bangun datar, dan posisi benda.
A11: 6 | B11: MUSTOFA ABDUL KARIM BENZEMA | E11: Ananda KARIM sangat baik dalam memahami materi operasi hitung, bangun datar, dan posisi benda. Hal yang perlu diperhatikan adalah ketelitian dalam proses pembelajaran.
A12: 7 | B12: RAZAN MUMTAZAH ZUBAIR | E12: Ananda RAZAN baik dalam memahami materi operasi hitung, bangun datar, dan posisi benda. Hal yang perlu diperhatikan adalah ketelitian dalam proses pembelajaran.
A13: 8 | B13: SHOFIYYAH MIZYANAH | E13: Ananda SHOFIYAH sangat baik dalam memahami materi operasi hitung, bangun datar, dan posisi benda.

Sheet JILID
A1: LAPORAN PEMBELAJARAN UMMI SD AL QUR'AN LANTABUR TAHUN PELAJARAN 2025/2026
A6: NAMA | B6: : | C6: ='DATA SISWA'!B9 -> ALIFAH HANANIYYA | D6: JILID | E6: : | F6: AL QUR'AN
A7: KELAS | B7: : | C7: 2 AL MULK | D7: SEMESTER | E7: : | F7: GANJIL
A9: JILID | C9: POKOK BAHASAN | D9: NILAI
D10: Huruf | F10: Keterangan
A11: I | C11: 1. Pengenalan huruf tunggal (Hijaiyah) Alif-Ya.
C12: 2. Pengenala huruf tunggal berharakat fathah A-Ya
C13: 3. Membaca 2-3 huruf tunggal berharakat fathah A-Ya
A14: II | C14: 1. Pengenalan harakat kasrah dan dhammah, fathatain, kasratain dan dhammahtain.
C15: 2. Pengenala huruf sambung Alif - Ya
C16: 3. Pengenalan Angka Arab 1-99
A17: III | C17: 1. Pengenalan tanda baca panjang (Mad Thabi'i)
C18: * Fathah diikuti Alif dan fathah panjang
C19: * Kasrah diikuti Ya' sukun dan kasrah panjang
C20: * Dhammah diikuti Wawu sukun dan dan kasrah panjang
C21: 2. Pengenalan tanda baca panjang (Mad wajib Muttashil dan Mad Jaiz Munfashil)
C22: 3. Pengenalan Angka Arab 100-500
A23: IV | C23: 1. Pengenalan huruf yang disukun ditekan membacanya
C24: 2. Pengenalan tanda Tasydid/Syiddah ditekan membacanya.
C25: 3. Membedakan cara membaca huruf-huruf
C26: * Tsa', Sin dan Syin yang disukun
C27: * 'Ain, Hamzah yang disukun.
C28: * Ha', Kha', dan Hha' yang disukun.
A29: V | C29: 1. Pengenalan cara membaca Waqaf/mewakafkan
C30: 2. Pengenalan bacaan Ghunnah/dengung
C31: 3. Pengenalan bacaan ikhfa/samar
C32: 4. Pengenalan bacaan Idgham Bighunnah
C33: 5. Pengenalan bacaan Iqlab
C34: 6. Pengenalan cara membaca lafadz Allah
A35: VI | C35: 1. Pengenalan bacaan Qalqalah/mantul
C36: 2. Pengenalan bacaan Idgham bilaghunnah
C37: 3. Pengenalan bacaan Izhar/jelas.
C38: 4. Pengenalan macam-macam tanda Waqaf/washal
C39: 5. Cara membaca Nun-iwadh di awal dan ditengah ayat
C40: 6. Membaca Ana, na-nya dibaca dipendek
A41: Al Qur'an | C41: 1. Melafadzkan Al Qur'an dengan lancar | D41: B
C42: 2. Membaca dengan makhorijul huruf yang benar | D42: A
C43: 3. Memahami tajwid yang benar | D43: A
A44: Al Qur'an (Ghorib) | C44: 1. Pengenalan bacaan Ghrib dalam Al-Qur'an
C45: 2. Pengenalan bacaan hati-hati dalam Al-Qur'an
...

Sheet TAHFIDZ
A1: LAPORAN PEMBELAJARAN UMMI SD AL QUR'AN LANTABUR TAHUN PELAJARAN 2025/2026
A6: NAMA | C6: ='DATA SISWA'!B9 -> ALIFAH HANANIYYA
A7: KELAS | C7: 2 AL MULK
A9: NO | B9: HAFALAN SURAT | C9: JILID | D9: NILAI | F9: NO | G9: HAFALAN SURAT | H9: JILID | I9: NILAI
A10: 1 | B10: An Naas | C10: 1 | F10: 21 | G10: Al Insyiroh | H10: Ghorib 1-14 (Ghorib 1) | I10: A
A11: 2 | B11: Al Falaq | F11: 22 | G11: Adh Dhuha | I11: A
A12: 3 | B12: Al Ikhlas | F12: 23 | G12: Al Lail | H12: Ghorib 15-28 (Ghorib 2) | I12: A
A13: 4 | B13: Al Lahab | F13: 24 | G13: Asy Syams | I13: A
A14: 5 | B14: An Nasr | C14: 2 | F14: 25 | G14: Al Balad | H14: Ghorib-Tajwid (tajwid 1) | I14: A
A15: 6 | B15: Al Kafirun | F15: 26 | G15: Al Fajr | I15: A
A16: 7 | B16: Al Kautsar | F16: 27 | G16: Al Ghosyiyah | H16: Ghorib-Tajwid (tajwid 2) | I16: A
A17: 8 | B17: Al Ma'un | C17: 3 | F17: 28 | G17: Al A'la
A18: 9 | B18: Al Quraisy | F18: 29 | G18: Ath Thoriq | H18: Pengembangan 1
A19: 10 | B19: Al Fiil | F19: 30 | G19: Al Buruj
A20: 11 | B20: Al Humazah | C20: 4 | F20: 31 | G20: Al Insyiqoq
A21: 12 | B21: Al 'Asr | F21: 32 | G21: Al Mutoffifin
A22: 13 | B22: At Takatsur | F22: 33 | G22: Al Infithor
A23: 14 | B23: Al Qori'ah | C23: 5 | F23: 34 | G23: At Takwir
A24: 15 | B24: Al 'Adiyat | F24: 35 | G24: Abasa
A25: 16 | B25: Al Zalzalah | C25: 6 | F25: 36 | G25: An Nazi'at
A26: 17 | B26: Al Bayyinah | F26: 37 | G26: An Naba'
A27: 18 | B27: Al Qodr | C27: Al Qur'an | F27: 1 | G27: Pemeliharaan hafalan juz 30 | H27: Pengembangan 2
A28: 19 | B28: Al 'Alaq | F28: 2 | G28: penambahan hafalan baru juz 29
A29: 20 | B29: At Tiin | C29: Ghorib 1-14 (Ghorib 1) | D29: A
A31: NO | B31: PENILAIAN | C31: HURUF | D31: PREDIKAT
A32: 1 | B32: 90-100 | C32: A | D32: Mumtaz
A33: 2 | B33: 75-89 | C33: B | D33: Jayyid
A34: 3 | B34: 66-74 | C34: C | D34: Maqbul
A36: Mengetahui | H36: Pekanbaru, 19 Desember 2025
A37: Kepala SD Al Qur'an Lantabur | E37: Orangtua/Wali | H37: Guru Tahfidz Al Qur'an
A40: KASMIDAR, S. Pd | E40: ='DATA SISWA'!M9 -> KHAIRUL ASHARI | H40: SYARIFAH SAWILAH, S.Si.
A41: NIY. 2403001 | H41: NIY. 2403003
A46: LAPORAN PEMBELAJARAN UMMI SD AL QUR'AN LANTABUR TAHUN PELAJARAN 2025/2026
A51: NAMA | C51: ='DATA SISWA'!B10 -> IZQIAN ARSALAN KUSUMA
A52: KELAS | C52: 2 AL MULK
A54: NO | B54: HAFALAN SURAT | C54: JILID | D54: NILAI | F54: NO | G54: HAFALAN SURAT | H54: JILID | I54: NILAI
A55: 1 | B55: An Naas | C55: 1 | F55: 21 | G55: Al Insyiroh | H55: Ghorib 1-14 (Ghorib 1) | I55: A
A56: 2 | B56: Al Falaq | F56: 22 | G56: Adh Dhuha | I56: A
A57: 3 | B57: Al Ikhlas | F57: 23 | G57: Al Lail | H57: Ghorib 15-28 (Ghorib 2) | I57: A
A58: 4 | B58: Al Lahab | F58: 24 | G58: Asy Syams | I58: A
...
